<?xml version="1.0"?>
<!-- created with Phobos 1.0.1 "Capricious Choutengan" -->
<robot name="qB">

 <material name="blue">
   <color rgba="0 0 0.8 1"/>
 </material>
 
 <material name="red">
   <color rgba="0.8 0 0 1"/>
 </material>

 <material name="white">
   <color rgba="1 1 1 1"/>
 </material>
 
 <material name="grey">
   <color rgba="0.6 0.6 0.6 1"/>
 </material>
 
 <material name="black">
   <color rgba="0.2 0.2 0.2 1"/>
 </material>
 

 <link name="base_link">
   <visual>
      <origin rpy="0 0 0" xyz="0 0 0"/>
      <geometry>
         <mesh filename="package://qb_description/meshes/base.dae"/>
      </geometry>
      <material name="black"/>
   </visual>
   <visual>
      <origin rpy="0 0 0" xyz="0 0 0"/>
      <geometry>
         <mesh filename="package://qb_description/meshes/shell.dae"/>
      </geometry>
      <material name="red"/>
   </visual>
   <visual>
      <origin rpy="0 0 0" xyz="0.09 0 0.062"/>
      <geometry>
         <mesh filename="package://qb_description/meshes/udoo.dae"/>
      </geometry>
      <material name="black"/>
   </visual>
   <visual>
      <origin rpy="0 0 0" xyz="0.27 0 0.058"/>
      <geometry>
         <mesh filename="package://qb_description/meshes/psu.dae"/>
      </geometry>
      <material name="black"/>
   </visual>
   <collision>
      <origin rpy="0 0 0" xyz="0 0 0"/>
      <geometry>
         <box size="0.42 0.42 0.42"/>
      </geometry>
   </collision>
 </link>

 <link name="l_caster_wheel_link">
   <visual>
      <origin rpy="0 0 0" xyz="0 0 0"/>
      <geometry>
         <mesh filename="package://qb_description/meshes/l_caster_wheel.dae"/>
      </geometry>
      <material name="grey"/>
   </visual>
   <collision>
      <origin rpy="0 0 0" xyz="-0.025 0 -0.02"/>
      <geometry>
         <box size="0.04 0.04 0.1"/>
      </geometry>
   </collision>
 </link>
 
 <link name="r_caster_wheel_link">
   <visual>
      <geometry>
         <mesh filename="package://qb_description/meshes/r_caster_wheel.dae"/>
      </geometry>
      <material name="grey"/>
   </visual>
   <collision>
      <origin rpy="0 0 0" xyz="-0.025 0 -0.02"/>
      <geometry>
         <box size="0.04 0.04 0.1"/>
      </geometry>
   </collision>
 </link>

 <link name="l_wheel_link">
   <visual>
      <geometry>
         <mesh filename="package://qb_description/meshes/l_wheel.dae"/>
      </geometry>
      <material name="black"/>
   </visual>
   <collision>
      <origin rpy="1.57079632679 0 0" xyz="0 0 0"/>
      <geometry>
         <cylinder length="0.055" radius="0.0852"/>
      </geometry>
   </collision>
 </link>
 
 <link name="r_wheel_link">
   <visual>
      <geometry>
         <mesh filename="package://qb_description/meshes/l_wheel.dae"/>
      </geometry>
      <material name="black"/>
   </visual>
   <collision>
      <origin rpy="-1.57079632679 0 0" xyz="0 0 0"/>
      <geometry>
         <cylinder length="0.055" radius="0.0852"/>
      </geometry>
   </collision>
 </link>
 
 <link name="laser_link">
   <visual>
      <geometry>
         <mesh filename="package://qb_description/meshes/lidar.dae"/>
      </geometry>
      <material name="blue"/>
   </visual>
 </link>
 
<!--<link name="d400_link">
   <visual>
      <geometry>
         <mesh filename="package://qb_description/meshes/d435.dae"/>
      </geometry>
      <material name="white"/>
   </visual>
 </link>

 <link name="t265_link">
   <visual>
      <geometry>
         <mesh filename="package://qb_description/meshes/t265.dae"/>
      </geometry>
      <material name="white"/>
   </visual>
 </link>-->


 <joint name="l_caster_wheel_joint" type="fixed">
   <origin rpy="0 0 0" xyz="0.3 0.15 0"/>
   <parent link="base_link"/>
   <child link="l_caster_wheel_link"/>
 </joint>
 
 <joint name="r_caster_wheel_joint" type="fixed">
   <origin rpy="0 0 0" xyz="0.3 -0.15 0"/>
   <parent link="base_link"/>
   <child link="r_caster_wheel_link"/>
 </joint>

 <joint name="l_wheel_joint" type="continuous">
   <axis xyz="0 1 0"/>
   <limit effort="3.0" velocity="6.28"/>
   <origin rpy="0 0 0" xyz="0 0.135 0"/>
   <parent link="base_link"/>
   <child link="l_wheel_link"/>
 </joint>

 <joint name="r_wheel_joint" type="continuous">
   <axis xyz="0 1 0"/>
   <limit effort="3.0" velocity="6.28"/>
   <origin rpy="3.141527 0 0" xyz="0 -0.135 0"/>
   <parent link="base_link"/>
   <child link="r_wheel_link"/>
 </joint>
 
 <joint name="laser_joint" type="fixed">
   <origin rpy="3.141527 0 0" xyz="0.22 0 0.001"/>
   <parent link="base_link"/>
   <child link="laser_link"/>
 </joint>

 <!--<joint name="d400_joint" type="fixed">
   <origin rpy="0 0 0" xyz="0.300 0 0.2"/>
   <parent link="base_link"/>
   <child link="d400_link"/>
 </joint>
 
<joint name="t265_joint" type="fixed">
   <origin rpy="0 0 0" xyz="0.305 0 0.225"/>
   <parent link="base_link"/>
   <child link="t265_link"/>
 </joint>-->

</robot>
