<?xml version="1.0" ?>
<robot name="qb" xmlns:xacro="http://www.ros.org/wiki/xacro">

<xacro:include filename="$(find qb_description)/urdf/materials.xacro" />
<xacro:include filename="$(find qb_description)/urdf/qb.trans" />
<xacro:include filename="$(find qb_description)/urdf/qb.gazebo" />
<link name="base_link">
  <inertial>
    <origin rpy="0 0 0" xyz="0.08517453560154699 0.001636240244356314 0.1850655388060331"/>
    <mass value="14"/>
    <inertia ixx="0.379166666667" ixy="-0.000605" ixz="0.002676" iyy="0.379166666667" iyz="-0.001318" izz="0.4725"/>
  </inertial>
  <visual>
    <origin rpy="0 0 0" xyz="0 0 0"/>
    <geometry>
      <mesh filename="package://qb_description/meshes/base_link.stl" scale="0.001 0.001 0.001"/>
    </geometry>
    <material name="silver"/>
  </visual>
  <collision>
    <origin rpy="0 0 0" xyz="0 0 0"/>
    <geometry>
      <mesh filename="package://qb_description/meshes/base_link.stl" scale="0.001 0.001 0.001"/>
    </geometry>
  </collision>
</link>

<link name="l_wheel_link">
  <inertial>
    <origin rpy="0 0 0" xyz="-6.007145793383156e-08 0.04051081667390975 9.236001824453055e-08"/>
    <mass value="3"/>
    <inertia ixx="0.0073" ixy="-0.0" ixz="0.0" iyy="0.0073" iyz="0.0" izz="0.0096"/>
  </inertial>
  <visual>
    <origin rpy="0 0 0" xyz="0.001625 -0.101197 -0.083775"/>
    <geometry>
      <mesh filename="package://qb_description/meshes/l_wheel_link.stl" scale="0.001 0.001 0.001"/>
    </geometry>
    <material name="silver"/>
  </visual>
  <collision>
    <origin rpy="1.57 0 0" xyz="0 0.04 0"/>
    <geometry>
      <cylinder radius="0.08" length="0.05"/>
      <!--<mesh filename="package://qb_description/meshes/l_wheel_link.stl" scale="0.001 0.001 0.001"/>-->
    </geometry>
  </collision>
</link>

<link name="r_wheel_link">
  <inertial>
    <origin rpy="0 0 0" xyz="-6.060328737737992e-08 -0.039512860885770704 1.3917224245263426e-07"/>
    <mass value="3"/>
    <inertia ixx="0.0073" ixy="0.0" ixz="-0.0" iyy="0.0073" iyz="-0.0" izz="0.0096"/>
  </inertial>
  <visual>
    <origin rpy="0 0 0" xyz="0.001625 0.098431 -0.083775"/>
    <geometry>
      <mesh filename="package://qb_description/meshes/r_wheel_link.stl" scale="0.001 0.001 0.001"/>
    </geometry>
    <material name="silver"/>
  </visual>
  <collision>
    <origin rpy="-1.57 0 0" xyz="0 -0.04 0"/>
    <geometry>
      <cylinder radius="0.08" length="0.05"/>
      <!--<mesh filename="package://qb_description/meshes/r_wheel_link.stl" scale="0.001 0.001 0.001"/>-->
    </geometry>
  </collision>
</link>

<link name="l_caster_link">
  <inertial>
    <origin rpy="0 0 0" xyz="0.0025889472718868545 -1.870937940406936e-07 -0.03221916382876208"/>
    <mass value="5"/>
    <inertia ixx="0.0135416666667" ixy="0.0" ixz="2.1e-05" iyy="0.0135416666667" iyz="-0.0" izz="0.00833333333333"/>
  </inertial>
  <visual>
    <origin rpy="0 0 0" xyz="-0.288 -0.191428 -0.095053"/>
    <geometry>
      <mesh filename="package://qb_description/meshes/l_caster_link.stl" scale="0.001 0.001 0.001"/>
    </geometry>
    <material name="silver"/>
  </visual>
  <collision>
    <origin rpy="0 0 0" xyz="-0.288 -0.191428 -0.095053"/>
    <geometry>
      <mesh filename="package://qb_description/meshes/l_caster_link.stl" scale="0.001 0.001 0.001"/>
    </geometry>
  </collision>
</link>

<link name="r_caster_link">
  <inertial>
    <origin rpy="0 0 0" xyz="0.002588950655702582 6.186932649532295e-08 -0.032219160354699364"/>
    <mass value="0.02"/>
    <inertia ixx="0.0135416666667" ixy="0.0" ixz="2.1e-05" iyy="0.0135416666667" iyz="-0.0" izz="0.00833333333333"/>
  </inertial>
  <visual>
    <origin rpy="0 0 0" xyz="-0.288 0.188178 -0.095053"/>
    <geometry>
      <mesh filename="package://qb_description/meshes/r_caster_link.stl" scale="0.001 0.001 0.001"/>
    </geometry>
    <material name="silver"/>
  </visual>
  <collision>
    <origin rpy="0 0 0" xyz="-0.288 0.188178 -0.095053"/>
    <geometry>
      <mesh filename="package://qb_description/meshes/r_caster_link.stl" scale="0.001 0.001 0.001"/>
    </geometry>
  </collision>
</link>

<link name="t265_link">
  <inertial>
    <origin rpy="0 0 0" xyz="-0.007003120392218842 0.0012343508315372854 9.087579541211532e-06"/>
    <mass value="0.12049783530780897"/>
    <inertia ixx="0.000118" ixy="-0.0" ixz="-0.0" iyy="8e-06" iyz="0.0" izz="0.000113"/>
  </inertial>
  <visual>
    <origin rpy="0 0 0" xyz="-0.310634 -0.0 -0.3272"/>
    <geometry>
      <mesh filename="package://qb_description/meshes/t265_link.stl" scale="0.001 0.001 0.001"/>
    </geometry>
    <material name="silver"/>
  </visual>
  <collision name="t265_collision_box">
    <origin rpy="0 0 0" xyz="0.03 -0.0 -0.2"/>
    <!--<origin rpy="0 0 0" xyz="-0.310634 -0.0 -0.3272"/>-->
    <geometry>
      <box size="0.03 0.4 0.05"/>
      <!--<mesh filename="package://qb_description/meshes/t265_link.stl" scale="0.001 0.001 0.001"/>-->
    </geometry>
  </collision>
</link>

<link name="d435_link">
  <inertial>
    <origin rpy="0 0 0" xyz="0.012749615420696164 -2.7032282874069266e-05 -5.2944468881488405e-05"/>
    <mass value="0.3760990765533483"/>
    <inertia ixx="0.000235" ixy="0.0" ixz="-0.0" iyy="3.5e-05" iyz="0.0" izz="0.000237"/>
  </inertial>
  <visual>
    <origin rpy="0 0 0" xyz="0.135 -0.0 -0.3025"/>
    <geometry>
      <mesh filename="package://qb_description/meshes/d435_link.stl" scale="0.001 0.001 0.001"/>
    </geometry>
    <material name="silver"/>
  </visual>
  <collision>
    <origin rpy="0 0 0" xyz="0.135 -0.0 -0.3025"/>
    <geometry>
      <mesh filename="package://qb_description/meshes/d435_link.stl" scale="0.001 0.001 0.001"/>
    </geometry>
  </collision>
</link>

<link name="laser_link">
  <inertial>
    <origin rpy="0 0 0" xyz="-0.009810635325917028 1.2751683593881238e-07 -0.016625365915204318"/>
    <mass value="0.3"/>
    <inertia ixx="0.000625" ixy="0.0" ixz="0.000121" iyy="0.000625" iyz="-0.0" izz="0.000125"/>
  </inertial>
  <visual>
    <origin rpy="0 0 0" xyz="-0.23 -0.0 -0.08"/>
    <geometry>
      <mesh filename="package://qb_description/meshes/laser_link.stl" scale="0.001 0.001 0.001"/>
    </geometry>
    <material name="silver"/>
  </visual>
  <collision>
    <origin rpy="0 0 0" xyz="-0.23 -0.0 -0.08"/>
    <geometry>
      <mesh filename="package://qb_description/meshes/laser_link.stl" scale="0.001 0.001 0.001"/>
    </geometry>
  </collision>
</link>

<joint name="l_wheel_joint" type="continuous">
  <origin rpy="0 0 0" xyz="-0.001625 0.101197 0.083775"/>
  <parent link="base_link"/>
  <child link="l_wheel_link"/>
  <axis xyz="0.0 1.0 0.0"/>
</joint>

<joint name="r_wheel_joint" type="continuous">
  <origin rpy="0 0 0" xyz="-0.001625 -0.098431 0.083775"/>
  <parent link="base_link"/>
  <child link="r_wheel_link"/>
  <axis xyz="0.0 1.0 0.0"/>
</joint>

<joint name="l_caster_joint" type="fixed">
  <origin rpy="0 0 0" xyz="0.288 0.191428 0.095053"/>
  <parent link="base_link"/>
  <child link="l_caster_link"/>
</joint>

<joint name="r_caster_joint" type="fixed">
  <origin rpy="0 0 0" xyz="0.288 -0.188178 0.095053"/>
  <parent link="base_link"/>
  <child link="r_caster_link"/>
</joint>

<joint name="t265_joint" type="fixed">
  <origin rpy="0 0 0" xyz="0.310634 0.0 0.3272"/>
  <parent link="base_link"/>
  <child link="t265_link"/>
</joint>

<joint name="d435_joint" type="fixed">
  <origin rpy="0 0 0" xyz="-0.135 0.0 0.3025"/>
  <parent link="base_link"/>
  <child link="d435_link"/>
</joint>

<joint name="lidar_joint" type="fixed">
  <origin rpy="3.141592 0 0" xyz="0.23 0.0 0.065"/>
  <parent link="base_link"/>
  <child link="laser_link"/>
</joint>

</robot>
