<?xml version="1.0"?>
<!-- created with Phobos 1.0.1 "Capricious Choutengan" -->
  <robot name="MiroBot">

    <material name="blue">
      <color rgba="0 0 0.8 1"/>
    </material>
    
    <material name="red">
      <color rgba="0.8 0 0 1"/>
    </material>

    <material name="white">
      <color rgba="1 1 1 1"/>
    </material>
    
    <material name="grey">
      <color rgba="0.6 0.6 0.6 1"/>
    </material>
    
    <material name="black">
      <color rgba="0.2 0.2 0.2 1"/>
    </material>
    

    <link name="base_link">
      <visual>
         <origin rpy="0 0 0" xyz="0 0 0"/>
         <geometry>
            <mesh filename="package://mirobot_description/meshes/base.dae"/>
         </geometry>
         <material name="black"/>
      </visual>
      <visual>
         <origin rpy="0 0 0" xyz="0.09 0 0.045"/>
         <geometry>
            <mesh filename="package://mirobot_description/meshes/frame.dae"/>
         </geometry>
         <material name="red"/>
      </visual>
      <visual>
         <origin rpy="0 0 0" xyz="0.09 0 0.075"/>
         <geometry>
            <mesh filename="package://mirobot_description/meshes/jetson.dae"/>
         </geometry>
         <material name="black"/>
      </visual>
      <collision>
         <origin rpy="0 0 0" xyz="0 0 0"/>
         <geometry>
            <box size="0.2 0.465 0.076"/>
         </geometry>
      </collision>
      <collision>
         <origin rpy="0 0 0" xyz="0.09 0 0.045"/>
         <geometry>
            <box size="0.44 0.4 0.023"/>
         </geometry>
      </collision>
      <collision>
         <origin rpy="0 0 0" xyz="0.09 0 0.075"/>
         <geometry>
            <box size="0.04 0.065 0.018"/>
         </geometry>
      </collision>
    </link>

    <link name="l_caster_wheel_link">
      <visual>
         <origin rpy="0 0 0" xyz="0 0 0"/>
         <geometry>
            <mesh filename="package://mirobot_description/meshes/l_caster_wheel.dae"/>
         </geometry>
         <material name="grey"/>
      </visual>
      <collision>
         <origin rpy="0 0 0" xyz="-0.025 0 -0.02"/>
         <geometry>
            <box size="0.04 0.04 0.1"/>
         </geometry>
      </collision>
    </link>
    
    <link name="r_caster_wheel_link">
      <visual>
         <geometry>
            <mesh filename="package://mirobot_description/meshes/r_caster_wheel.dae"/>
         </geometry>
         <material name="grey"/>
      </visual>
      <collision>
         <origin rpy="0 0 0" xyz="-0.025 0 -0.02"/>
         <geometry>
            <box size="0.04 0.04 0.1"/>
         </geometry>
      </collision>
    </link>

    <link name="l_wheel_link">
      <visual>
         <geometry>
            <mesh filename="package://mirobot_description/meshes/l_wheel.dae"/>
         </geometry>
         <material name="black"/>
      </visual>
      <collision>
         <origin rpy="1.57079632679 0 0" xyz="0 0 0"/>
         <geometry>
            <cylinder length="0.055" radius="0.0852"/>
         </geometry>
      </collision>
    </link>
    
    <link name="r_wheel_link">
      <visual>
         <geometry>
            <mesh filename="package://mirobot_description/meshes/l_wheel.dae"/>
         </geometry>
         <material name="black"/>
      </visual>
      <collision>
         <origin rpy="-1.57079632679 0 0" xyz="0 0 0"/>
         <geometry>
            <cylinder length="0.055" radius="0.0852"/>
         </geometry>
      </collision>
    </link>
    
    <link name="lidar_link">
      <visual>
         <geometry>
            <mesh filename="package://mirobot_description/meshes/lidar.dae"/>
         </geometry>
         <material name="blue"/>
      </visual>
      <collision>
         <origin rpy="0 0 0" xyz="-0.025 0 0"/>
         <geometry>
            <box size="0.1 0.065 0.062"/>
         </geometry>
      </collision>
    </link>
    
    <link name="camera_link">
      <visual>
         <geometry>
            <mesh filename="package://mirobot_description/meshes/camera.dae"/>
         </geometry>
         <material name="white"/>
      </visual>
      <collision>
         <geometry>
            <box size="0.02 0.115 0.03"/>
         </geometry>
      </collision>
    </link>


    <joint name="l_caster_wheel_joint" type="fixed">
      <origin xyz="0.3 0.15 0" rpy="0 0 0"/>
      <parent link="base_link"/>
      <child link="l_caster_wheel_link"/>
    </joint>
    
    <joint name="r_caster_wheel_joint" type="fixed">
      <origin xyz="0.3 -0.15 0" rpy="0 0 0"/>
      <parent link="base_link"/>
      <child link="r_caster_wheel_link"/>
    </joint>

    <joint name="l_wheel_joint" type="continuous">
      <axis xyz="1 0 0"/>
      <limit effort="3.0" velocity="6.28"/>
      <origin xyz="0 0.26 0" rpy="0 0 0"/>
      <parent link="base_link"/>
      <child link="l_wheel_link"/>
    </joint>

    <joint name="r_wheel_joint" type="continuous">
      <axis xyz="1 0 0"/>
      <limit effort="3.0" velocity="6.28"/>
      <origin xyz="0 -0.26 0" rpy="3.141527 0 0"/>
      <parent link="base_link"/>
      <child link="r_wheel_link"/>
    </joint>
    
    <joint name="lidar_joint" type="fixed">
      <origin rpy="0 0 0" xyz="0.26 0 0.075"/>
      <parent link="base_link"/>
      <child link="lidar_link"/>
    </joint>
    
    <joint name="camera_joint" type="fixed">
      <origin rpy="0 0 0" xyz="0.3 0 0.073"/>
      <parent link="base_link"/>
      <child link="camera_link"/>
    </joint>

  </robot>
