<?xml version="1.0"?>
<!-- created with Phobos 1.0.1 "Capricious Choutengan" -->
  <robot name="MiroBot">

    <material name="blue">
      <color rgba="0 0 0.8 1"/>
    </material>
    
    <material name="red">
      <color rgba="0.8 0 0 1"/>
    </material>

    <material name="white">
      <color rgba="1 1 1 1"/>
    </material>
    
    <material name="grey">
      <color rgba="0.6 0.6 0.6 1"/>
    </material>
    
    <material name="black">
      <color rgba="0.2 0.2 0.2 1"/>
    </material>
    


    <link name="base_link">
      <visual>
         <origin rpy="0 0 0" xyz="0 0 0"/>
         <geometry>
            <mesh filename="package://mirobot_description/meshes/base.dae"/>
         </geometry>
         <material name="black"/>
      </visual>
      <visual>
         <origin rpy="0 0 0" xyz="0.09 0 0.045"/>
         <geometry>
            <mesh filename="package://mirobot_description/meshes/frame.dae"/>
         </geometry>
         <material name="red"/>
      </visual>
      <visual>
         <origin rpy="0 0 0" xyz="0.09 0 0.075"/>
         <geometry>
            <mesh filename="package://mirobot_description/meshes/jetson.dae"/>
         </geometry>
         <material name="black"/>
      </visual>
      <collision>
         <origin rpy="0 0 0" xyz="0 0 0"/>
         <geometry>
            <box size="0.2 0.465 0.076"/>
         </geometry>
      </collision>
      <collision>
         <origin rpy="0 0 0" xyz="0.09 0 0.045"/>
         <geometry>
            <box size="0.44 0.4 0.023"/>
         </geometry>
      </collision>
      <collision>
         <origin rpy="0 0 0" xyz="0.09 0 0.075"/>
         <geometry>
            <box size="0.04 0.065 0.018"/>
         </geometry>
      </collision>
      <inertial>
        <origin xyz="0 0 0" rpy="0 0 0"/>
        <mass value="0.002"/>
        <inertia ixx="0.002" ixy="0" ixz="0" iyy="0.002" iyz="0" izz="0.002"/>
      </inertial>
    </link>

    <link name="l_caster_wheel_link">
      <visual>
         <origin rpy="0 0 0" xyz="0 0 0"/>
         <geometry>
            <mesh filename="package://mirobot_description/meshes/l_caster_wheel.dae"/>
         </geometry>
         <material name="grey"/>
      </visual>
      <collision>
         <origin rpy="0 0 0" xyz="-0.025 0 -0.02"/>
         <geometry>
            <box size="0.04 0.04 0.1"/>
         </geometry>
      </collision>
      <inertial>
        <origin xyz="0 0 0" rpy="0 0 0"/>
        <mass value="0.001"/>
        <inertia ixx="0.001" ixy="0" ixz="0" iyy="0.001" iyz="0" izz="0.001"/>
      </inertial>
    </link>
    
    <link name="r_caster_wheel_link">
      <visual>
         <geometry>
            <mesh filename="package://mirobot_description/meshes/r_caster_wheel.dae"/>
         </geometry>
         <material name="grey"/>
      </visual>
      <collision>
         <origin rpy="0 0 0" xyz="-0.025 0 -0.02"/>
         <geometry>
            <box size="0.04 0.04 0.1"/>
         </geometry>
      </collision>
      <inertial>
        <mass value="0.001"/>
        <inertia ixx="0.001" ixy="0" ixz="0" iyy="0.001" iyz="0" izz="0.001"/>
      </inertial>
    </link>

    <link name="l_wheel_link">
      <visual>
         <geometry>
            <mesh filename="package://mirobot_description/meshes/l_wheel.dae"/>
         </geometry>
         <material name="black"/>
      </visual>
      <collision>
         <origin rpy="1.57079632679 0 0" xyz="0 0 0"/>
         <geometry>
            <cylinder length="0.055" radius="0.0852"/>
         </geometry>
      </collision>
      <inertial>
        <mass value="0.001"/>
        <inertia ixx="0.001" ixy="0" ixz="0" iyy="0.001" iyz="0" izz="0.001"/>
      </inertial>
    </link>
    
    <link name="r_wheel_link">
      <visual>
         <geometry>
            <mesh filename="package://mirobot_description/meshes/l_wheel.dae"/>
         </geometry>
         <material name="black"/>
      </visual>
      <collision>
         <origin rpy="-1.57079632679 0 0" xyz="0 0 0"/>
         <geometry>
            <cylinder length="0.055" radius="0.0852"/>
         </geometry>
      </collision>
      <inertial>
        <mass value="0.001"/>
        <inertia ixx="0.001" ixy="0" ixz="0" iyy="0.001" iyz="0" izz="0.001"/>
      </inertial>
    </link>
    
    <link name="lidar_link">
      <visual>
         <geometry>
            <mesh filename="package://mirobot_description/meshes/lidar.dae"/>
         </geometry>
         <material name="blue"/>
      </visual>
      <collision>
         <origin rpy="0 0 0" xyz="-0.025 0 0"/>
         <geometry>
            <box size="0.1 0.065 0.062"/>
         </geometry>
      </collision>
      <inertial>
        <mass value="0.001"/>
        <inertia ixx="0.001" ixy="0" ixz="0" iyy="0.001" iyz="0" izz="0.001"/>
      </inertial>
    </link>
    
    <link name="camera_link">
      <visual>
         <geometry>
            <mesh filename="package://mirobot_description/meshes/camera.dae"/>
         </geometry>
         <material name="white"/>
      </visual>
      <collision>
         <geometry>
            <box size="0.02 0.115 0.03"/>
         </geometry>
      </collision>
      <inertial>
        <mass value="0.001"/>
        <inertia ixx="0.001" ixy="0" ixz="0" iyy="0.001" iyz="0" izz="0.001"/>
      </inertial>
    </link>

    <joint name="l_caster_wheel_joint" type="fixed">
      <origin xyz="0.3 0.15 0" rpy="0 0 0"/>
      <parent link="base_link"/>
      <child link="l_caster_wheel_link"/>
    </joint>
    
    <joint name="r_caster_wheel_joint" type="fixed">
      <origin xyz="0.3 -0.15 0" rpy="0 0 0"/>
      <parent link="base_link"/>
      <child link="r_caster_wheel_link"/>
    </joint>

    <joint name="l_wheel_joint" type="continuous">
      <axis xyz="1 0 0"/>
      <limit effort="3.0" velocity="6.28"/>
      <origin xyz="0 0.26 0" rpy="0 0 0"/>
      <parent link="base_link"/>
      <child link="l_wheel_link"/>
    </joint>

    <joint name="r_wheel_joint" type="continuous">
      <axis xyz="1 0 0"/>
      <limit effort="3.0" velocity="6.28"/>
      <origin xyz="0 -0.26 0" rpy="3.141527 0 0"/>
      <parent link="base_link"/>
      <child link="r_wheel_link"/>
    </joint>
    
    <joint name="lidar_joint" type="fixed">
      <origin rpy="0 0 0" xyz="0.26 0 0.075"/>
      <parent link="base_link"/>
      <child link="lidar_link"/>
    </joint>
    
    <joint name="camera_joint" type="fixed">
      <origin rpy="0 0 0" xyz="0.3 0 0.073"/>
      <parent link="base_link"/>
      <child link="camera_link"/>
    </joint>


    <gazebo reference="lidar_link">
    <sensor type="gpu_ray" name="head_hokuyo_sensor">
       <pose>0 0 0 0 0 0</pose>
       <visualize>false</visualize>
       <update_rate>40</update_rate>
       <ray>
          <scan>
          <horizontal>
             <samples>720</samples>
             <resolution>1</resolution>
             <min_angle>-1.570796</min_angle>
             <max_angle>1.570796</max_angle>
          </horizontal>
          </scan>
          <range>
          <min>0.10</min>
          <max>30.0</max>
          <resolution>0.01</resolution>
          </range>
          <noise>
          <type>gaussian</type>
          <!-- Noise parameters based on published spec for Hokuyo laser
                achieving "+-30mm" accuracy at range < 10m.  A mean of 0.0m and
                stddev of 0.01m will put 99.7% of samples within 0.03m of the true
                reading. -->
          <mean>0.0</mean>
          <stddev>0.01</stddev>
          </noise>
       </ray>
       <plugin name="gazebo_ros_head_hokuyo_controller" filename="libgazebo_ros_gpu_laser.so">
          <topicName>/mirobot/laser/scan</topicName>
          <frameName>lidar_link</frameName>
       </plugin>
    </sensor>
    </gazebo>

    <gazebo reference="camera_link">
       <sensor type="camera" name="camera">
         <update_rate>30.0</update_rate>
         <camera name="head">
           <horizontal_fov>1.3962634</horizontal_fov>
           <image>
             <width>800</width>
             <height>600</height>
             <format>R8G8B8</format>
           </image>
           <clip>
             <near>0.02</near>
             <far>300</far>
           </clip>
           <noise>
             <type>gaussian</type>
             <!-- Noise is sampled independently per pixel on each frame.
                  That pixel's noise value is added to each of its color
                  channels, which at that point lie in the range [0,1]. -->
             <mean>0.0</mean>
             <stddev>0.007</stddev>
           </noise>
         </camera>
         <plugin name="camera_controller" filename="libgazebo_ros_camera.so">
           <alwaysOn>true</alwaysOn>
           <updateRate>0.0</updateRate>
           <cameraName>mirobot/camera</cameraName>
           <imageTopicName>image_raw</imageTopicName>
           <cameraInfoTopicName>camera_info</cameraInfoTopicName>
           <frameName>camera_link</frameName>
           <hackBaseline>0.07</hackBaseline>
           <distortionK1>0.0</distortionK1>
           <distortionK2>0.0</distortionK2>
           <distortionK3>0.0</distortionK3>
           <distortionT1>0.0</distortionT1>
           <distortionT2>0.0</distortionT2>
         </plugin>
       </sensor>
    </gazebo>
       
    <gazebo>
       <plugin name="differential_drive_controller" filename="libgazebo_ros_diff_drive.so">
          <alwaysOn>true</alwaysOn>
          <updateRate>30.0</updateRate>
          <leftJoint>l_wheel_joint</leftJoint>
          <rightJoint>r_wheel_joint</rightJoint>
          <wheelSeparation>0.5380</wheelSeparation>
          <wheelDiameter>0.2410</wheelDiameter>
          <torque>20</torque>
          <commandTopic>cmd_vel</commandTopic>
          <odometryTopic>odom</odometryTopic>
          <odometryFrame>odom</odometryFrame>
          <robotBaseFrame>base_link</robotBaseFrame>
       </plugin>
    </gazebo>


  </robot>
